2022-04-13 21:52:53,952 INFO    MainThread:31567 [wandb_setup.py:_flush():75] Loading settings from /home/ido/.config/wandb/settings
2022-04-13 21:52:53,952 INFO    MainThread:31567 [wandb_setup.py:_flush():75] Loading settings from /home/ido/projects/MNIST_comparison/wandb/settings
2022-04-13 21:52:53,952 INFO    MainThread:31567 [wandb_setup.py:_flush():75] Loading settings from environment variables: {}
2022-04-13 21:52:53,952 INFO    MainThread:31567 [wandb_setup.py:_flush():75] Inferring run settings from compute environment: {'program_relpath': 'train_RF_wine.py', 'program': '/home/ido/projects/MNIST_comparison/train_RF_wine.py'}
2022-04-13 21:52:53,952 INFO    MainThread:31567 [wandb_init.py:_log_setup():405] Logging user logs to /home/ido/projects/MNIST_comparison/wandb/run-20220413_215253-3pnpdkeu/logs/debug.log
2022-04-13 21:52:53,952 INFO    MainThread:31567 [wandb_init.py:_log_setup():406] Logging internal logs to /home/ido/projects/MNIST_comparison/wandb/run-20220413_215253-3pnpdkeu/logs/debug-internal.log
2022-04-13 21:52:53,952 INFO    MainThread:31567 [wandb_init.py:init():439] calling init triggers
2022-04-13 21:52:53,952 INFO    MainThread:31567 [wandb_init.py:init():442] wandb.init called with sweep_config: {}
config: {}
2022-04-13 21:52:53,952 INFO    MainThread:31567 [wandb_init.py:init():492] starting backend
2022-04-13 21:52:53,952 INFO    MainThread:31567 [backend.py:_multiprocessing_setup():99] multiprocessing start_methods=fork,spawn,forkserver, using: spawn
2022-04-13 21:52:53,960 INFO    MainThread:31567 [backend.py:ensure_launched():219] starting backend process...
2022-04-13 21:52:53,962 INFO    MainThread:31567 [backend.py:ensure_launched():224] started backend process with pid: 31594
2022-04-13 21:52:53,963 INFO    MainThread:31567 [wandb_init.py:init():501] backend started and connected
2022-04-13 21:52:53,965 INFO    MainThread:31567 [wandb_init.py:init():565] updated telemetry
2022-04-13 21:52:53,966 INFO    MainThread:31567 [wandb_init.py:init():596] communicating run to backend with 30 second timeout
2022-04-13 21:53:22,824 ERROR   Thread-1  :31567 [retry.py:__call__():126] Retry attempt failed:
Traceback (most recent call last):
  File "/home/ido/miniconda3/envs/sparsity_probe_env/lib/python3.9/site-packages/urllib3/connectionpool.py", line 449, in _make_request
    six.raise_from(e, None)
  File "<string>", line 3, in raise_from
  File "/home/ido/miniconda3/envs/sparsity_probe_env/lib/python3.9/site-packages/urllib3/connectionpool.py", line 444, in _make_request
    httplib_response = conn.getresponse()
  File "/home/ido/miniconda3/envs/sparsity_probe_env/lib/python3.9/http/client.py", line 1371, in getresponse
    response.begin()
  File "/home/ido/miniconda3/envs/sparsity_probe_env/lib/python3.9/http/client.py", line 319, in begin
    version, status, reason = self._read_status()
  File "/home/ido/miniconda3/envs/sparsity_probe_env/lib/python3.9/http/client.py", line 280, in _read_status
    line = str(self.fp.readline(_MAXLINE + 1), "iso-8859-1")
  File "/home/ido/miniconda3/envs/sparsity_probe_env/lib/python3.9/socket.py", line 704, in readinto
    return self._sock.recv_into(b)
  File "/home/ido/miniconda3/envs/sparsity_probe_env/lib/python3.9/ssl.py", line 1241, in recv_into
    return self.read(nbytes, buffer)
  File "/home/ido/miniconda3/envs/sparsity_probe_env/lib/python3.9/ssl.py", line 1099, in read
    return self._sslobj.read(len, buffer)
socket.timeout: The read operation timed out

During handling of the above exception, another exception occurred:

Traceback (most recent call last):
  File "/home/ido/miniconda3/envs/sparsity_probe_env/lib/python3.9/site-packages/requests/adapters.py", line 440, in send
    resp = conn.urlopen(
  File "/home/ido/miniconda3/envs/sparsity_probe_env/lib/python3.9/site-packages/urllib3/connectionpool.py", line 785, in urlopen
    retries = retries.increment(
  File "/home/ido/miniconda3/envs/sparsity_probe_env/lib/python3.9/site-packages/urllib3/util/retry.py", line 550, in increment
    raise six.reraise(type(error), error, _stacktrace)
  File "/home/ido/miniconda3/envs/sparsity_probe_env/lib/python3.9/site-packages/urllib3/packages/six.py", line 770, in reraise
    raise value
  File "/home/ido/miniconda3/envs/sparsity_probe_env/lib/python3.9/site-packages/urllib3/connectionpool.py", line 703, in urlopen
    httplib_response = self._make_request(
  File "/home/ido/miniconda3/envs/sparsity_probe_env/lib/python3.9/site-packages/urllib3/connectionpool.py", line 451, in _make_request
    self._raise_timeout(err=e, url=url, timeout_value=read_timeout)
  File "/home/ido/miniconda3/envs/sparsity_probe_env/lib/python3.9/site-packages/urllib3/connectionpool.py", line 340, in _raise_timeout
    raise ReadTimeoutError(
urllib3.exceptions.ReadTimeoutError: HTTPSConnectionPool(host='api.wandb.ai', port=443): Read timed out. (read timeout=10)

During handling of the above exception, another exception occurred:

Traceback (most recent call last):
  File "/home/ido/miniconda3/envs/sparsity_probe_env/lib/python3.9/site-packages/wandb/sdk/lib/retry.py", line 102, in __call__
    result = self._call_fn(*args, **kwargs)
  File "/home/ido/miniconda3/envs/sparsity_probe_env/lib/python3.9/site-packages/wandb/sdk/internal/internal_api.py", line 140, in execute
    return self.client.execute(*args, **kwargs)
  File "/home/ido/miniconda3/envs/sparsity_probe_env/lib/python3.9/site-packages/wandb/vendor/gql-0.2.0/wandb_gql/client.py", line 52, in execute
    result = self._get_result(document, *args, **kwargs)
  File "/home/ido/miniconda3/envs/sparsity_probe_env/lib/python3.9/site-packages/wandb/vendor/gql-0.2.0/wandb_gql/client.py", line 60, in _get_result
    return self.transport.execute(document, *args, **kwargs)
  File "/home/ido/miniconda3/envs/sparsity_probe_env/lib/python3.9/site-packages/wandb/vendor/gql-0.2.0/wandb_gql/transport/requests.py", line 38, in execute
    request = requests.post(self.url, **post_args)
  File "/home/ido/miniconda3/envs/sparsity_probe_env/lib/python3.9/site-packages/requests/api.py", line 117, in post
    return request('post', url, data=data, json=json, **kwargs)
  File "/home/ido/miniconda3/envs/sparsity_probe_env/lib/python3.9/site-packages/requests/api.py", line 61, in request
    return session.request(method=method, url=url, **kwargs)
  File "/home/ido/miniconda3/envs/sparsity_probe_env/lib/python3.9/site-packages/requests/sessions.py", line 529, in request
    resp = self.send(prep, **send_kwargs)
  File "/home/ido/miniconda3/envs/sparsity_probe_env/lib/python3.9/site-packages/requests/sessions.py", line 645, in send
    r = adapter.send(request, **kwargs)
  File "/home/ido/miniconda3/envs/sparsity_probe_env/lib/python3.9/site-packages/requests/adapters.py", line 532, in send
    raise ReadTimeout(e, request=request)
requests.exceptions.ReadTimeout: HTTPSConnectionPool(host='api.wandb.ai', port=443): Read timed out. (read timeout=10)
2022-04-13 21:53:23,966 INFO    MainThread:31567 [interface_shared.py:_communicate_run():322] couldn't get run from backend
2022-04-13 21:53:23,966 ERROR   MainThread:31567 [wandb_init.py:init():601] backend process timed out
2022-04-13 21:53:23,966 ERROR   MainThread:31567 [wandb_init.py:init():610] encountered error: Error communicating with wandb process
try: wandb.init(settings=wandb.Settings(start_method='fork'))
or:  wandb.init(settings=wandb.Settings(start_method='thread'))
For more info see: https://docs.wandb.ai/library/init#init-start-error
2022-04-13 21:53:41,307 WARNING MainThread:31567 [wandb_init.py:init():975] interrupted
Traceback (most recent call last):
  File "/home/ido/miniconda3/envs/sparsity_probe_env/lib/python3.9/site-packages/wandb/sdk/wandb_init.py", line 954, in init
    run = wi.init()
  File "/home/ido/miniconda3/envs/sparsity_probe_env/lib/python3.9/site-packages/wandb/sdk/wandb_init.py", line 614, in init
    backend.cleanup()
  File "/home/ido/miniconda3/envs/sparsity_probe_env/lib/python3.9/site-packages/wandb/sdk/backend/backend.py", line 250, in cleanup
    self.wandb_process.join()
  File "/home/ido/miniconda3/envs/sparsity_probe_env/lib/python3.9/multiprocessing/process.py", line 149, in join
    res = self._popen.wait(timeout)
  File "/home/ido/miniconda3/envs/sparsity_probe_env/lib/python3.9/multiprocessing/popen_fork.py", line 43, in wait
    return self.poll(os.WNOHANG if timeout == 0.0 else 0)
  File "/home/ido/miniconda3/envs/sparsity_probe_env/lib/python3.9/multiprocessing/popen_fork.py", line 27, in poll
    pid, sts = os.waitpid(self.pid, flag)
KeyboardInterrupt
